
Raw Benchmark Output
====================

Running Convolution 3D on Octuplets using NumPy/CPU
    commit: `#ab3ae314f108b7046dead79b06cc6c836f2380ff <https://bitbucket.org/bohrium/bohrium/commits/ab3ae314f108b7046dead79b06cc6c836f2380ff>`_,
    time: 2015-03-27 04:05:53.722646.

    command: ``  / u s r / b i n / t i m e   - v   - o   / h o m e / b h b u i l d e r / b e n c h p r e s s / b h - j o b - 7 c 0 5 b 0 5 3 - 0 5 e 0 - 4 5 4 6 - 8 4 8 e - 6 5 e f 5 a 1 0 e a a a . s h - 2 . t i m e   p y t h o n   b e n c h m a r k / p y t h o n / c o n v o l v e _ 3 d . p y   - - s i z e = 1 0 0   - - b o h r i u m = F a l s e``

Run 00
~~~~~~
    stdout::

        N/A

    stderr::

        Traceback (most recent call last):
          File "benchmark/python/convolve_3d.py", line 59, in <module>
            main()
          File "benchmark/python/convolve_3d.py", line 50, in main
            image, image_filter = convolve_3d_init(N, B)
          File "benchmark/python/convolve_3d.py", line 33, in convolve_3d_init
            kernel  = gen_3d_filter(fsize, 13.0)
          File "benchmark/python/convolve_3d.py", line 23, in gen_3d_filter
            kernel[filterZ + kernelrad, filterY + kernelrad,filterX + kernelrad] = caleuler * np.exp(-distance)
        IndexError: index 100 is out of bounds for axis 2 with size 100
        Error in [node:impl]: /home/bhbuilder/.local/lib/libbh_vem_node.so: cannot open shared object file: No such file or directory
        



Run 01
~~~~~~
    stdout::

        N/A

    stderr::

        Traceback (most recent call last):
          File "benchmark/python/convolve_3d.py", line 59, in <module>
            main()
          File "benchmark/python/convolve_3d.py", line 50, in main
            image, image_filter = convolve_3d_init(N, B)
          File "benchmark/python/convolve_3d.py", line 33, in convolve_3d_init
            kernel  = gen_3d_filter(fsize, 13.0)
          File "benchmark/python/convolve_3d.py", line 23, in gen_3d_filter
            kernel[filterZ + kernelrad, filterY + kernelrad,filterX + kernelrad] = caleuler * np.exp(-distance)
        IndexError: index 100 is out of bounds for axis 2 with size 100
        Error in [node:impl]: /home/bhbuilder/.local/lib/libbh_vem_node.so: cannot open shared object file: No such file or directory
        



Run 02
~~~~~~
    stdout::

        N/A

    stderr::

        Traceback (most recent call last):
          File "benchmark/python/convolve_3d.py", line 59, in <module>
            main()
          File "benchmark/python/convolve_3d.py", line 50, in main
            image, image_filter = convolve_3d_init(N, B)
          File "benchmark/python/convolve_3d.py", line 33, in convolve_3d_init
            kernel  = gen_3d_filter(fsize, 13.0)
          File "benchmark/python/convolve_3d.py", line 23, in gen_3d_filter
            kernel[filterZ + kernelrad, filterY + kernelrad,filterX + kernelrad] = caleuler * np.exp(-distance)
        IndexError: index 100 is out of bounds for axis 2 with size 100
        Error in [node:impl]: /home/bhbuilder/.local/lib/libbh_vem_node.so: cannot open shared object file: No such file or directory
        



